<?xml version="1.0" ?>
<robot name="nndrone" xmlns:xacro="http://www.ros.org/wiki/xacro">

  <xacro:include filename="$(find nndrone_description)/urdf/materials.xacro" />
  <!-- <xacro:include filename="$(find nndrone_description)/urdf/nndrone.trans" /> -->
  <xacro:include filename="$(find nndrone_description)/urdf/nndrone.gazebo" />
  <xacro:include filename="$(find nndrone_description)/urdf/plugins/plugins.gazebo" />


  <link name="base_link">
    <inertial>
      <origin rpy="0 0 -1.5708" xyz="0.0 0.0 -0.055"/>
      <mass value="0.5"/>
      <inertia  ixx="0.0017350964305" ixy="0" ixz="0" iyy="0.00253016077525" iyz="0" izz="0.00365126915346" />
    </inertial>
    <visual>
      <origin rpy="0 0 -1.5708" xyz="0 0 -0.055"/>
      <geometry>
        <mesh filename="package://nndrone_description/meshes/base_link.stl" scale="0.001 0.001 0.001"/>
      </geometry>
      <material name="silver"/>
    </visual>
    <collision>
      <origin rpy="0 0 -1.5708" xyz="0 0 -0.055"/> 
      <geometry>
        <mesh filename="package://nndrone_description/meshes/base_link.stl" scale="0.001 0.001 0.001"/>
      </geometry>
      <surface>
          <contact>
            <ode>
              <max_vel>100.0</max_vel>
              <min_depth>0.001</min_depth>
            </ode>
          </contact>
          <friction>
            <ode>
              <mu>1.0</mu>
              <mu2>1.0</mu2>
            </ode>
          </friction>
        </surface>
    </collision>
  </link>
  <link name="prop_cw_1">
    <inertial>
      <origin rpy="0 0 0" xyz="0.0 0.0 0.0"/>
      <mass value="0.027"/>
      <inertia  ixx="2.16576359834e-05" ixy="0" ixz="0" iyy="2.78597602888e-05" iyz="0" izz="4.9003356158e-05" />
    </inertial>
    <visual>
      <origin rpy="0 0 0" xyz="-0.0985 -0.0695 -0.055"/>
      <geometry>
        <mesh filename="package://nndrone_description/meshes/prop_cw_1_1.stl" scale="0.001 0.001 0.001"/>
      </geometry>
      <material name="red"/>
    </visual>
    <collision>
      <origin rpy="0 0 0" xyz="-0.0985 -0.0695 -0.055"/>
      <geometry>
        <mesh filename="package://nndrone_description/meshes/prop_cw_1_1.stl" scale="0.001 0.001 0.001"/>
      </geometry>
    </collision>
  </link>

  <link name="prop_ccw_3">
    <inertial>
      <origin rpy="0 0 0" xyz="0.0 0.0 0.0"/>
      <mass value="0.027"/>
      <inertia  ixx="2.16576359834e-05" ixy="0" ixz="0" iyy="2.78597602888e-05" iyz="0" izz="4.9003356158e-05" />
    </inertial>
    <visual>
      <origin rpy="0 0 0" xyz="0.0985 -0.0695 -0.055"/>
      <geometry>
        <mesh filename="package://nndrone_description/meshes/prop_ccw_3_1.stl" scale="0.001 0.001 0.001"/>
      </geometry>
      <material name="red"/>
    </visual>
    <collision>
      <origin rpy="0 0 0" xyz="0.0985 -0.0695 -0.055"/>
      <geometry>
        <mesh filename="package://nndrone_description/meshes/prop_ccw_3_1.stl" scale="0.001 0.001 0.001"/>
      </geometry>
    </collision>
  </link>

  <link name="prop_cw_2">
    <inertial>
      <origin rpy="0 0 0" xyz="0.0 0.0 0.0"/>
      <mass value="0.027"/>
      <inertia  ixx="2.16576359834e-05" ixy="0" ixz="0" iyy="2.78597602888e-05" iyz="0" izz="4.9003356158e-05" />
    </inertial>
    <visual>
      <origin rpy="0 0 0" xyz="0.0985 0.0869 -0.055"/>
      <geometry>
        <mesh filename="package://nndrone_description/meshes/prop_cw_2_1.stl" scale="0.001 0.001 0.001"/>
      </geometry>
      <material name="red"/>
    </visual>
    <collision>
      <origin rpy="0 0 0" xyz="0.0985 0.0869 -0.055"/>
      <geometry>
        <mesh filename="package://nndrone_description/meshes/prop_cw_2_1.stl" scale="0.001 0.001 0.001"/>
      </geometry>
    </collision>
  </link>

  <link name="prop_ccw_4">
    <inertial>
      <origin rpy="0 0 0" xyz="0.0 0.0 0.0"/>
      <mass value="0.027"/>
      <inertia  ixx="2.16576359834e-05" ixy="0" ixz="0" iyy="2.78597602888e-05" iyz="0" izz="4.9003356158e-05" />
    </inertial>
    <visual>
      <origin rpy="0 0 0" xyz="-0.0985 0.0869 -0.055"/>
      <geometry>
        <mesh filename="package://nndrone_description/meshes/prop_ccw_4_1.stl" scale="0.001 0.001 0.001"/>
      </geometry>
      <material name="red"/>
    </visual>
    <collision>
      <origin rpy="0 0 0" xyz="-0.0985 0.0869 -0.055"/>
      <geometry>
        <mesh filename="package://nndrone_description/meshes/prop_ccw_4_1.stl" scale="0.001 0.001 0.001"/>
      </geometry>
    </collision>
  </link>

  <link name="lidar_1">
    <inertial>
      <origin rpy="0 0 0" xyz="1.50702293634589e-17 0.001172866940571421 0.02762648466802698"/>
      <mass value="0.01"/>
      <inertia ixx="0.0" ixy="0.0" ixz="0.0" iyy="1e-06" iyz="-0.0" izz="1e-06"/>
    </inertial>
    <visual>
      <origin rpy="0 0 0" xyz="-0.0 -0.077 -0.0415"/>
      <geometry>
        <mesh filename="package://nndrone_description/meshes/lidar_1.stl" scale="0.001 0.001 0.001"/>
      </geometry>
      <material name="black"/>
    </visual>

  </link>

  <link name="pi_camera_1">
    <inertial>
      <origin rpy="0 0 0" xyz="-1.0210978849032173e-12 0.0 -0.004779083094555998"/>
      <mass value="0.01"/>
      <inertia ixx="0.0" ixy="0.0" ixz="0.0" iyy="0.0" iyz="-0.0" izz="0.0"/>
    </inertial>
    <visual>
      <origin rpy="0 0 0" xyz="0.0 -0.06725 -0.036"/>
      <geometry>
        <mesh filename="package://nndrone_description/meshes/pi_camera_1.stl" scale="0.001 0.001 0.001"/>
      </geometry>
      <material name="black"/>
    </visual>

  </link>

  <link name='imu_link'>
      <inertial>
        <origin rpy="0 0 0" xyz="0 0 0" />
        <mass value="0.15" />
        <inertia  ixx="0.000520528929149" ixy="0" ixz="0" iyy="0.000759048232575" iyz="0" izz="0.00109538074604" />
      </inertial>
      <visual>
      <origin rpy="0 0 0" xyz="0.0 -0.06725 -0.036"/>
      <geometry>
        <mesh filename="package://nndrone_description/meshes/imu.stl" scale="0.001 0.001 0.001"/>
      </geometry>
      <material name="black"/>
      </visual>
  </link>


  <joint name="Rev1" type="continuous">
    <origin rpy="0 0 0" xyz="0.0695 -0.0985 0.001"/>
    <parent link="base_link"/>
    <child link="prop_cw_1"/>
    <axis xyz="0.0 0.0 1.0"/>
  </joint>

  <joint name="Rev3" type="continuous">
    <origin rpy="0 0 0" xyz="0.0695 0.0985 0.001"/>
    <parent link="base_link"/>
    <child link="prop_ccw_3"/>
    <axis xyz="0.0 0.0 1.0"/>
  </joint>

  <joint name="Rev2" type="continuous">
    <origin rpy="0 0 0" xyz="-0.0869 0.0985 0.001"/>
    <parent link="base_link"/>
    <child link="prop_cw_2"/>
    <axis xyz="0.0 0.0 1.0"/>
  </joint>

  <joint name="Rev4" type="continuous">
    <origin rpy="0 0 0" xyz="-0.0869 -0.0985 0.001"/>
    <parent link="base_link"/>
    <child link="prop_ccw_4"/>
    <axis xyz="0.0 0.0 1.0"/>
  </joint>

  <joint name="lidar_joint" type="fixed">
    <origin rpy="0 0 1.5708" xyz="0.077 0.0 -0.015"/>
    <parent link="base_link"/>
    <child link="lidar_1"/>
  </joint>

  <joint name="rpi_cam_joint" type="fixed">
    <origin rpy="0 0 0" xyz="0.06725 0.0 -0.020"/>
    <parent link="base_link"/>
    <child link="pi_camera_1"/>
  </joint>

  <joint name="imu_joint" type="fixed">
      <origin rpy="0 3.141593 0.0" xyz="0 0 0.0" />
      <parent link="base_link" />
      <child link="imu_link" />
      <dynamics damping="0.7"/>
      <physics>
        <ode>
          <implicit_spring_damper>1</implicit_spring_damper>
        </ode>
      </physics>

  </joint>

</robot>
